<?xml version="1.0"?>
<robot xmlns:xacro="http://www.ros.org/wiki/xacro">

  <xacro:include filename="$(find tr1_description)/urdf/head/head.gazebo.xacro" />
	<xacro:include filename="$(find tr1_description)/urdf/head/head.transmission.xacro" />

	<link name="neck_base_link">
		<collision>
			<geometry>
        <mesh filename="package://tr1_description/meshes/dae/neck_base.dae" scale="0.001 0.001 0.001"/>
			</geometry>
			<origin rpy="1.5708 0 0"/>
		</collision>
		<inertial>
			<mass value="0.005"/>
			<inertia ixx="0.001" iyy="0.001" izz="0.001" ixy="0" ixz="0" iyz="0" />
		</inertial>
		<visual>
			<geometry>
        <mesh filename="package://tr1_description/meshes/dae/neck_base.dae" scale="0.001 0.001 0.001"/>
			</geometry>
			<origin rpy="1.5708 0 0"/>
		</visual>
	</link>

	<link name="neck_link">
		<collision>
			<geometry>
        <mesh filename="package://tr1_description/meshes/dae/neck.dae" scale="0.001 0.001 0.001"/>
			</geometry>
			<origin rpy="1.5708 0 0"/>
		</collision>
		<inertial>
			<mass value="0.005"/>
			<inertia ixx="0.001" iyy="0.001" izz="0.001" ixy="0" ixz="0" iyz="0" />
		</inertial>
		<visual>
			<geometry>
        <mesh filename="package://tr1_description/meshes/dae/neck.dae" scale="0.001 0.001 0.001"/>
			</geometry>
			<origin rpy="1.5708 0 0"/>
		</visual>
	</link>

	<link name="head_link">
		<collision>
			<geometry>
        <mesh filename="package://tr1_description/meshes/dae/head.dae" scale="0.001 0.001 0.001"/>
			</geometry>
			<origin rpy="1.5708 0 0"/>
		</collision>
		<inertial>
			<mass value="0.005"/>
			<inertia ixx="0.001" iyy="0.001" izz="0.001" ixy="0" ixz="0" iyz="0" />
		</inertial>
		<visual>
			<geometry>
        <mesh filename="package://tr1_description/meshes/dae/head.dae" scale="0.001 0.001 0.001"/>
			</geometry>
			<origin rpy="0 -1.5708 -1.5708"/>
		</visual>
	</link>

  <link name="camera_link">
    <collision>
      <origin xyz="0 0 0" rpy="0 0 0" />
      <geometry>
				<box size="0.01 0.01 0.01" />
      </geometry>
    </collision>
    <inertial>
      <mass value="0.00001" />
      <inertia ixx="0.0001" ixy="0" ixz="0" iyy="0.0001" iyz="0" izz="0.0001" />
    </inertial>
  </link>

	<joint name="camera_joint" type="fixed">
		<parent link="head_link"/>
		<child link="camera_link"/>
		<origin rpy="0 0 1.5708" xyz="0 0.115 0.035"/>
		<axis xyz="1 0 0" />
	</joint>

	<joint name="JointHeadPan" type="revolute">
		<parent link="neck_base_link"/>
		<child link="neck_link"/>
		<origin xyz="0 0 0.035"/>
    <axis xyz="0 0 1"/>
		<limit effort="1.0" lower="-3.1415" upper="3.1415" velocity="0.5"/>
    <dynamics damping="0.1" friction="0.1"/>
	</joint>

	<joint name="JointHeadTilt" type="revolute">
		<parent link="neck_link"/>
		<child link="head_link"/>
		<origin xyz="0 0.090789 0.09"/>
    <axis xyz="1 0 0"/>
		<limit effort="1.0" lower="-0.9" upper="0.4" velocity="0.5"/>
    <dynamics damping="0.1" friction="0.1"/>
	</joint>

</robot>


